Workbook

Sheet Quant_Structured
A1: Teacher_ID | B1: Name of the interviewer | C1: Name of the note-taker | D1: District of respondent teacher | E1: Gender of respondent | F1: Date of the interview | G1: Subject taught by teacher | H1: Years of teaching experience | I1: Subject taught by teacher__Hindi | J1: Subject taught by teacher__English | K1: Subject taught by teacher__Social Science | L1: Subject taught by teacher__Maths | M1: Subject taught by teacher__Sanskrit | N1: Subject taught by teacher__Science | O1: Subject taught by teacher__Other | P1: Avg no. of classroom periods taken in a day | Q1: Activities participated over 2025-26 academic year__Subject Training | R1: Activities participated over 2025-26 academic year__Digital Training | S1: Activities participated over 2025-26 academic year__CLSS | T1: Activities participated over 2025-26 academic year__SKG | U1: Activities participated over 2025-26 academic year__Webex | V1: Activities participated over 2025-26 academic year__YTL | W1: Activities participated over 2025-26 academic year__APF Demo Sessions | X1: Activities participated over 2025-26 academic year__SIR | Y1: Activities participated over 2025-26 academic year__Muskaan Dreams- DIET Training | Z1: Activities participated over 2025-26 academic year__HM Training | AA1: Activities participated over 2025-26 academic year__Election related Duties | AB1: Activities participated over 2025-26 academic year__Any other | AC1: Do teachers find subject in-person training useful or helpful | AD1: Training resources received from in-person training__PPT | AE1: Training resources received from in-person training__Margdarshika_Teaching Plan__Modules | AF1: Training resources received from in-person training__ToT | AG1: Training resources received from in-person training__Not received | AH1: Have they applied given resources_teaching lesson plan__ modules in their classroom | AI1: Does teacher find SKG Sheekh ki Yatra useful | AJ1: Does teacher find Webex useful | AK1: Does teacher find YTL useful | AL1: Are there any online courses teacher has done in last 1 year | AM1: Does teacher think digital or online courses are an effective way for teachers to learn | AN1: How many hours teacher can allocate to engage with digital courses__ digital learning | AO1: Timing to do online or digital courses__learning__During school hours | AP1: Timing to do online or digital courses__learning__After school | AQ1: Timing to do online or digital courses__learning__During holidays or weekends | AR1: Most engaging features of DIKSHA digital course__Animated videos | AS1: Most engaging features of DIKSHA digital course__Real classroom examples | AT1: Most engaging features of DIKSHA digital course__Interactive questions__quizzes | AU1: Most engaging features of DIKSHA digital course__Readings__resources | AV1: Most engaging features of DIKSHA digital course__Assessments | AW1: Most engaging features of DIKSHA digital course__Post work | AX1: Most engaging features of DIKSHA digital course__Nothing | AY1: Source of information on DIKSHA digital course__WhatsApp posters | AZ1: Source of information on DIKSHA digital course__Dashboard | BA1: Source of information on DIKSHA digital course__JSK Instruction on whatsapp group | BB1: Source of information on DIKSHA digital course__CLSS | BC1: Source of information on DIKSHA digital course__VC | BD1: Source of information on DIKSHA digital course__Word of mouth | BE1: Source of information on DIKSHA digital course__Any other | BF1: Effective source of information to receive program related information | BG1: Effective source of information to receive program related information__JSK Whatsapp | BH1: Effective source of information to receive program related information__School Whatsapp | BI1: Effective source of information to receive program related information__Letter | BJ1: Effective source of information to receive program related information__Other | BK1: Does teacher know about DIKSHA Courses and platform | BL1: Reason for not doing DIKSHA course__Time issue | BM1: Reason for not doing DIKSHA course__Other engagement | BN1: Reason for not doing DIKSHA course__Technical issue | BO1: Reason for not doing DIKSHA course__Not aware | BP1: Reason for not doing DIKSHA course__Not found useful | BQ1: No. of CLSS attended by teacher | BR1: CLSS topics recalled__कक्षा प्रबंधन के शुरुआती प्रयास | BS1: CLSS topics recalled__पूर्वज्ञान से शुरु, समूहकार्य से सीख | BT1: CLSS topics recalled__प्रभावी गृहकार्य | BU1: CLSS topics recalled__पुनरवलोकन एवं समेकन | BV1: CLSS topics recalled__प्रभावी पुनरावृत्ति | BW1: CLSS topics recalled__No topic recalled | BX1: CLSS learning solved classroom challenge | BY1: Processes to cascade CLSS learnings at school level__Resources shared in the school whatsapp group | BZ1: Processes to cascade CLSS learnings at school level__Participating teacher share their notes | CA1: Processes to cascade CLSS learnings at school level__Participating teacher verbally cascade the learning Peer learning discussions | CB1: Processes to cascade CLSS learnings at school level__No learnings shared or no set process adopted | CC1: Processes to cascade CLSS learnings at school level__Other | CD1: Could teacher recall RSK MP as attendance platform for CLSS | CE1: What challenges do they face in filling attendance and feedback form post the samwad__Awareness Issue | CF1: What challenges do they face in filling attendance and feedback form post the samwad__Session end rush for teachers to leave the venue | CG1: What challenges do they face in filling attendance and feedback form post the samwad__Not perceived important | CH1: What challenges do they face in filling attendance and feedback form post the samwad__Unwilling teachers | CI1: What challenges do they face in filling attendance and feedback form post the samwad__others | CJ1: Does teacher know about CLSS and it's format | CK1: Reasons of non-participation in CLSS__Could find time | CL1: Reasons of non-participation in CLSS__Not instructed to attend | CM1: Reasons of non-participation in CLSS__Busy with other work | CN1: Reasons of non-participation in CLSS__Didn't find any information | CO1: Reasons of non-participation in CLSS__Was not aware | CP1: Reasons of non-participation in CLSS__Others | CQ1: Are there any online courses teacher has done in last 1 year If yes, mention course name and platform | CR1: _index | CS1: Name of the online platforms used by the teacher | CT1: Diksha Course | CU1: DIKSHA | CV1: iGOT | CW1: Subject Training | CY1: Did Online Course
A2: 1 | B2: Rashmi Mishra | C2: Vaibhav Tambe | D2: Bhind | E2: Male | F2: 46183 | G2: Social Science | H2: 24 | I2: 0 | J2: 0 | K2: 1 | L2: 0 | M2: 0 | N2: 0 | O2: 0 | P2: 3 | Q2: 1 | R2: 1 | S2: 1 | T2: 0 | U2: 0 | V2: 0 | W2: 0 | X2: 1 | Y2: 0 | Z2: 1 | AA2: 1 | AB2: 1 | AC2: Yes | AD2: 0 | AE2: 1 | AF2: 0 | AG2: 0 | AH2: Not sure | AL2: Yes | AM2: No | AN2: 1 hr | AO2: 1 | AP2: 1 | AQ2: 0 | AR2: 0 | AS2: 0 | AT2: 0 | AU2: 0 | AV2: 1 | AW2: 0 | AY2: 0 | AZ2: 0 | BA2: 1 | BB2: 0 | BC2: 0 | BD2: 0 | BE2: 0 | BF2: JSK Whatsapp | BG2: 1 | BH2: 0 | BI2: 0 | BJ2: 0 | BK2: Yes | BQ2: 3 | BX2: Yes | BY2: 0 | BZ2: 0 | CA2: 0 | CB2: 0 | CC2: 1 | CD2: No | CE2: 0 | CF2: 0 | CG2: 1 | CH2: 0 | CI2: 0 | CJ2: Yes | CK2: 0 | CL2: 0 | CM2: 0 | CN2: 0 | CO2: 0 | CP2: 0 | CR2: 1 | CS2: =Qual_FreeText!Z2 -> DIKSHA | CT2: =Qual_FreeText!X2 -> Education Department (DIET) | CU2: 1 | CV2: 0 | CW2: =Qual_FreeText!M2 -> Subject Training, CLSS, Digital Training (PLC) | CX2: 1 | CY2: 1
A3: 2 | B3: Ritesh Pandey | C3: Vaibhav Kurwade | D3: Balaghat | E3: Male | F3: 46183 | G3: Social Science | H3: 37 | I3: 0 | J3: 0 | K3: 1 | L3: 0 | M3: 0 | N3: 0 | O3: 0 | P3: 4 | Q3: 1 | R3: 1 | S3: 1 | T3: 0 | U3: 0 | V3: 0 | W3: 0 | X3: 0 | Y3: 0 | Z3: 0 | AA3: 0 | AB3: 0 | AC3: Yes | AD3: 0 | AE3: 1 | AF3: 0 | AG3: 0 | AH3: Not sure | AL3: Yes | AM3: Yes | AN3: 4-5 hrs | AO3: 0 | AP3: 1 | AQ3: 0 | AR3: 0 | AS3: 0 | AT3: 1 | AU3: 0 | AV3: 0 | AW3: 1 | AY3: 1 | AZ3: 0 | BA3: 0 | BB3: 0 | BC3: 0 | BD3: 1 | BE3: 0 | BF3: JSK Whatsapp | BG3: 1 | BH3: 0 | BI3: 0 | BJ3: 0 | BK3: Yes | BQ3: 4 | BX3: No | BY3: 0 | BZ3: 0 | CA3: 0 | CB3: 0 | CC3: 1 | CD3: Yes | CE3: 0 | CF3: 0 | CG3: 0 | CH3: 1 | CI3: 0 | CJ3: No | CK3: 0 | CL3: 0 | CM3: 0 | CN3: 0 | CO3: 0 | CP3: 0 | CR3: 2 | CS3: =Qual_FreeText!Z3 -> DIKSHA and Karmayogi | CT3: =Qual_FreeText!X3 -> 0 | CU3: 1 | CV3: 0 | CW3: =Qual_FreeText!M3 -> Teacher took part in three days block level training in the month of July, after that he participated in the almost all CLSS from Aug to Jan. | CY3: 1
A4: 3 | B4: Aishwarya Yadav | C4: Jay Prakash | D4: Rajgarh | E4: Male | F4: 46184 | G4: Social Science | H4: 40 | I4: 0 | J4: 0 | K4: 1 | L4: 0 | M4: 0 | N4: 0 | O4: 0 | P4: 3 | Q4: 1 | R4: 1 | S4: 1 | T4: 0 | U4: 1 | V4: 1 | W4: 0 | X4: 0 | Y4: 0 | Z4: 0 | AA4: 0 | AB4: 0 | AC4: Yes | AD4: 0 | AE4: 0 | AF4: 0 | AG4: 1 | AJ4: No | AK4: No | AL4: Yes | AM4: Yes | AN4: 4-5 hrs | AO4: 1 | AP4: 1 | AQ4: 0 | AR4: 1 | AS4: 0 | AT4: 0 | AU4: 0 | AV4: 0 | AW4: 0 | AY4: 0 | AZ4: 0 | BA4: 1 | BB4: 0 | BC4: 0 | BD4: 1 | BE4: 0 | BF4: JSK Whatsapp | BG4: 1 | BH4: 0 | BI4: 0 | BJ4: 0 | BQ4: 5 | BX4: Yes | BY4: 0 | BZ4: 0 | CA4: 0 | CB4: 0 | CC4: 1 | CD4: No | CE4: 0 | CF4: 0 | CG4: 0 | CH4: 0 | CI4: 1 | CR4: 3 | CS4: =Qual_FreeText!Z4 -> दीक्षा App | CT4: =Qual_FreeText!X4 -> आपने बताया की आपने मानसिक तनाव कैसे कम करें इस पर online कोर्स किया हैं. | CU4: 1 | CV4: 0 | CW4: =Qual_FreeText!M4 -> Digital course, CLSS, sub Training | CY4: 1
A5: 4 | B5: Rajesh Solanki | C5: Shalu Sharma | D5: Betul | E5: Female | F5: 46184 | G5: Hindi Social Science | H5: 31 | I5: 1 | J5: 0 | K5: 1 | L5: 0 | M5: 0 | N5: 0 | O5: 0 | P5: 6 | Q5: 1 | R5: 1 | S5: 1 | T5: 1 | U5: 0 | V5: 1 | W5: 0 | X5: 0 | Y5: 0 | Z5: 0 | AA5: 0 | AB5: 0 | AC5: Yes | AD5: 0 | AE5: 0 | AF5: 1 | AG5: 0 | AH5: No | AI5: No | AK5: No | AL5: Yes | AM5: Yes | AN5: 1 hr | AO5: 0 | AP5: 1 | AQ5: 0 | AR5: 1 | AS5: 0 | AT5: 1 | AU5: 1 | AV5: 0 | AW5: 0 | AY5: 1 | AZ5: 0 | BA5: 1 | BB5: 1 | BC5: 0 | BD5: 0 | BE5: 0 | BF5: JSK Whatsapp | BG5: 1 | BH5: 0 | BI5: 0 | BJ5: 0 | BQ5: 3 | BX5: No | BY5: 0 | BZ5: 0 | CA5: 0 | CB5: 1 | CC5: 0 | CD5: No | CE5: 0 | CF5: 1 | CG5: 0 | CH5: 0 | CI5: 0 | CR5: 4 | CS5: =Qual_FreeText!Z5 -> Mygov and DIKSHA | CT5: =Qual_FreeText!X5 -> Suchna ka adhikar | CU5: 1 | CV5: 0 | CW5: =Qual_FreeText!M5 -> She could not recall | CY5: 1
A6: 5 | B6: Pushpendra Singh | C6: Other | D6: Satna | E6: Male | F6: 46183 | G6: Social Science | H6: 16 | I6: 0 | J6: 0 | K6: 1 | L6: 0 | M6: 0 | N6: 0 | O6: 0 | P6: 6 | Q6: 1 | R6: 0 | S6: 1 | T6: 0 | U6: 0 | V6: 0 | W6: 0 | X6: 0 | Y6: 0 | Z6: 0 | AA6: 0 | AB6: 0 | AC6: Yes | AD6: 1 | AE6: 1 | AF6: 0 | AG6: 0 | AH6: Yes | AL6: Yes | AM6: Yes | AN6: 2 hr | AO6: 1 | AP6: 0 | AQ6: 1 | BK6: Yes | BL6: 1 | BM6: 1 | BN6: 0 | BO6: 0 | BP6: 0 | BQ6: 5 | BX6: Yes | BY6: 0 | BZ6: 1 | CA6: 1 | CB6: 0 | CC6: 0 | CD6: Yes | CE6: 1 | CF6: 0 | CG6: 0 | CH6: 0 | CI6: 1 | CJ6: Yes | CK6: 0 | CL6: 0 | CM6: 0 | CN6: 0 | CO6: 0 | CP6: 0 | CR6: 5 | CS6: =Qual_FreeText!Z6 -> DIKSHA APP | CT6: =Qual_FreeText!X6 -> DIKSHA | CU6: 1 | CV6: 0 | CW6: =Qual_FreeText!M6 -> Teacher has participated in 5 CLSS throughout the year at JSK and one Block level subject training on new NCERT book of Class-6. | CX6: 1 | CY6: 1
A7: 6 | B7: Dharmendra Mishra | C7: Bhanu Priya | D7: Sagar | E7: Male | F7: 46183 | G7: Maths Science | H7: 15 | I7: 0 | J7: 0 | K7: 0 | L7: 1 | M7: 0 | N7: 1 | O7: 0 | P7: 6 | Q7: 1 | R7: 1 | S7: 1 | T7: 1 | U7: 0 | V7: 0 | W7: 0 | X7: 1 | Y7: 0 | Z7: 0 | AA7: 1 | AB7: 1 | AC7: Yes | AD7: 0 | AE7: 0 | AF7: 0 | AG7: 1 | AI7: Yes | AL7: Yes | AM7: Yes | AN7: 4-5 hrs | AO7: 0 | AP7: 1 | AQ7: 0 | AR7: 1 | AS7: 0 | AT7: 1 | AU7: 0 | AV7: 1 | AW7: 0 | AY7: 0 | AZ7: 0 | BA7: 1 | BB7: 0 | BC7: 0 | BD7: 0 | BE7: 0 | BF7: JSK Whatsapp | BG7: 1 | BH7: 0 | BI7: 0 | BJ7: 0 | BQ7: 4 | BX7: Yes | BY7: 0 | BZ7: 0 | CA7: 0 | CB7: 0 | CC7: 1 | CD7: Yes | CE7: 0 | CF7: 0 | CG7: 0 | CH7: 0 | CI7: 1 | CR7: 6 | CS7: =Qual_FreeText!Z7 -> DIKSHA, Karmyogi | CT7: =Qual_FreeText!X7 -> PLC, AI | CU7: 1 | CV7: 0 | CW7: =Qual_FreeText!M7 -> 1. Attended 4 CLSS - August, sept, oct, Jan 2. SIR- Nov- Dec 3. Subject Specific Training- June -July | CX7: 2 | CY7: 1
A8: 7 | B8: Shalu Sharma | C8: Rajesh Solanki | D8: Betul | E8: Male | F8: 46185 | G8: Maths Science | H8: 34 | I8: 0 | J8: 0 | K8: 0 | L8: 1 | M8: 0 | N8: 1 | O8: 0 | P8: 6 | Q8: 1 | R8: 0 | S8: 1 | T8: 0 | U8: 0 | V8: 1 | W8: 0 | X8: 1 | Y8: 0 | Z8: 0 | AA8: 0 | AB8: 0 | AC8: Yes | AD8: 1 | AE8: 1 | AF8: 0 | AG8: 0 | AH8: No | AK8: Yes | AL8: Yes | AM8: Yes | AO8: 1 | AP8: 0 | AQ8: 0 | BK8: Yes | BL8: 1 | BM8: 0 | BN8: 0 | BO8: 0 | BP8: 0 | BQ8: 3 | BX8: No | BY8: 0 | BZ8: 0 | CA8: 1 | CB8: 0 | CC8: 0 | CD8: Yes | CE8: 0 | CF8: 1 | CG8: 0 | CH8: 0 | CI8: 0 | CR8: 7 | CS8: =Qual_FreeText!Z8 -> MyGov and DIKSHA courses | CT8: =Qual_FreeText!X8 -> Some course on mulyanakan, couldn't remember the name of the course done on DIKSHA | CU8: 1 | CV8: 0 | CW8: =Qual_FreeText!M8 -> He participated in both Math and Science in person training. He mentioned that he attends YTL sometimes but he could not recall any topic discussed but he had idea about the paathyojana shared for science. he also shared an example from science training (chumbak). | CX8: 2 | CY8: 1
A9: 8 | B9: Rashmi Mishra | C9: Vaibhav Tambe | D9: Morena | E9: Female | F9: 46185 | G9: Maths | H9: 17 | I9: 0 | J9: 0 | K9: 0 | L9: 1 | M9: 0 | N9: 0 | O9: 0 | P9: 6 | Q9: 1 | R9: 1 | S9: 1 | T9: 0 | U9: 0 | V9: 0 | W9: 0 | X9: 0 | Y9: 0 | Z9: 0 | AA9: 0 | AB9: 0 | AC9: Yes | AD9: 0 | AE9: 1 | AF9: 0 | AG9: 0 | AH9: Yes | AL9: Yes | AM9: No | AO9: 1 | AP9: 0 | AQ9: 0 | AR9: 0 | AS9: 0 | AT9: 1 | AU9: 0 | AV9: 1 | AW9: 0 | AY9: 0 | AZ9: 0 | BA9: 1 | BB9: 0 | BC9: 0 | BD9: 0 | BE9: 0 | BF9: JSK Whatsapp | BG9: 1 | BH9: 0 | BI9: 0 | BJ9: 0 | BQ9: 5 | BX9: Yes | BY9: 0 | BZ9: 0 | CA9: 0 | CB9: 0 | CC9: 1 | CD9: Yes | CE9: 1 | CF9: 0 | CG9: 0 | CH9: 0 | CI9: 1 | CR9: 8 | CS9: =Qual_FreeText!Z9 -> DIKSHA | CT9: =Qual_FreeText!X9 -> Didn't remember course name. | CU9: 1 | CV9: 0 | CW9: =Qual_FreeText!M9 -> Subject training, CLSS, Digital Training | CX9: 1 | CY9: 1
A10: 9 | B10: Ritesh Pandey | C10: Vaibhav Kurwade | D10: Balaghat | E10: Female | F10: 46184 | G10: Hindi Social Science Sanskrit | H10: 18 | I10: 1 | J10: 0 | K10: 1 | L10: 0 | M10: 1 | N10: 0 | O10: 0 | P10: 4 | Q10: 1 | R10: 1 | S10: 1 | T10: 0 | U10: 0 | V10: 0 | W10: 0 | X10: 0 | Y10: 0 | Z10: 0 | AA10: 0 | AB10: 0 | AC10: Yes | AD10: 0 | AE10: 0 | AF10: 0 | AG10: 1 | AL10: Yes | AM10: Yes | AN10: 2 hr | AO10: 1 | AP10: 0 | AQ10: 0 | AR10: 0 | AS10: 0 | AT10: 1 | AU10: 0 | AV10: 0 | AW10: 0 | AY10: 1 | AZ10: 0 | BA10: 0 | BB10: 0 | BC10: 0 | BD10: 0 | BE10: 0 | BF10: JSK Whatsapp | BG10: 1 | BH10: 0 | BI10: 0 | BJ10: 0 | BQ10: 2 | BX10: No | BY10: 0 | BZ10: 0 | CA10: 1 | CB10: 0 | CC10: 0 | CD10: Yes | CE10: 0 | CF10: 0 | CG10: 0 | CH10: 0 | CI10: 1 | CJ10: Yes | CK10: 0 | CL10: 0 | CM10: 0 | CN10: 0 | CO10: 0 | CP10: 0 | CR10: 9 | CS10: =Qual_FreeText!Z10 -> Diksha and I-got | CT10: =Qual_FreeText!X10 -> AI course, Inclusive education (Samavesi shiksha on DIKSHA) | CU10: 1 | CV10: 1 | CW10: =Qual_FreeText!M10 -> Teacher took part in the subject training in the month of july, after that teacher attended 2 CLSS, and she attended digital training on I got karmayogi and on diksha. | CX10: 1 | CY10: 1
A11: 10 | B11: Aishwarya Yadav | C11: Jay Prakash | D11: Rajgarh | E11: Male | F11: 46185 | G11: Maths Science | H11: 27 | I11: 0 | J11: 0 | K11: 0 | L11: 1 | M11: 0 | N11: 1 | O11: 0 | P11: 6 | Q11: 1 | R11: 1 | S11: 1 | T11: 0 | U11: 0 | V11: 1 | W11: 0 | X11: 0 | Y11: 0 | Z11: 1 | AA11: 0 | AB11: 0 | AC11: Yes | AD11: 0 | AE11: 1 | AF11: 0 | AG11: 0 | AH11: Yes | AK11: Yes | AL11: Yes | AM11: Yes | AN11: 1 hr | AO11: 0 | AP11: 1 | AQ11: 0 | AR11: 1 | AS11: 1 | AT11: 1 | AU11: 1 | AV11: 0 | AW11: 0 | AY11: 0 | AZ11: 0 | BA11: 1 | BB11: 0 | BC11: 0 | BD11: 0 | BE11: 0 | BF11: JSK Whatsapp | BG11: 1 | BH11: 0 | BI11: 0 | BJ11: 0 | BQ11: 5 | BX11: Yes | BY11: 1 | BZ11: 0 | CA11: 0 | CB11: 0 | CC11: 0 | CD11: No | CE11: 0 | CF11: 0 | CG11: 0 | CH11: 0 | CI11: 1 | CR11: 10 | CS11: =Qual_FreeText!Z11 -> कर्मयोगी App के माध्यम से किये हैं. And DIKSHA | CT11: =Qual_FreeText!X11 -> कोर्स का नाम याद नहीं आ रहा हैं. | CU11: 1 | CV11: 0 | CW11: =Qual_FreeText!M11 -> SUB TRAININING, DIGITAL COURCE, CLSS, YTL, HM TRAINING | CX11: 1 | CY11: 1
A12: 11 | B12: Ritesh Pandey | C12: Vaibhav Kurwade | D12: Balaghat | E12: Female | F12: 46185 | G12: Social Science | H12: 16 | I12: 0 | J12: 0 | K12: 1 | L12: 0 | M12: 0 | N12: 0 | O12: 0 | P12: 6 | Q12: 1 | R12: 1 | S12: 1 | T12: 1 | U12: 0 | V12: 1 | W12: 0 | X12: 0 | Y12: 0 | Z12: 0 | AA12: 0 | AB12: 0 | AC12: Yes | AD12: 0 | AE12: 0 | AF12: 0 | AG12: 1 | AI12: Yes | AK12: Yes | AL12: Yes | AM12: Yes | AN12: 4-5 hrs | AO12: 1 | AP12: 1 | AQ12: 0 | AR12: 0 | AS12: 0 | AT12: 0 | AU12: 1 | AV12: 0 | AW12: 0 | AY12: 1 | AZ12: 0 | BA12: 0 | BB12: 0 | BC12: 0 | BD12: 0 | BE12: 0 | BF12: JSK Whatsapp | BG12: 1 | BH12: 0 | BI12: 0 | BJ12: 0 | BQ12: 5 | BX12: No | BY12: 0 | BZ12: 0 | CA12: 1 | CB12: 0 | CC12: 0 | CD12: Yes | CE12: 0 | CF12: 0 | CG12: 0 | CH12: 0 | CI12: 1 | CJ12: Yes | CK12: 0 | CL12: 0 | CM12: 0 | CN12: 0 | CO12: 0 | CP12: 0 | CR12: 11 | CS12: =Qual_FreeText!Z12 -> I got Karmayogi, Diksha | CT12: =Qual_FreeText!X12 -> not able to recall the name of the courses | CU12: 1 | CV12: 1 | CW12: =Qual_FreeText!M12 -> Teacher took part in the two days subject training at block level in the month of July, She attended all CLSS from Aug to Jan, and completed the digital course on I got platform. Also did one course on diksha but not able to recall the name of the course. | CX12: 1 | CY12: 1
A13: 12 | B13: Sonali Patidar | C13: Dilip Kag | D13: Khargone | E13: Female | F13: 46184 | G13: Social Science Maths | H13: 3 | I13: 0 | J13: 0 | K13: 1 | L13: 1 | M13: 0 | N13: 0 | O13: 0 | P13: 4 | Q13: 1 | R13: 1 | S13: 1 | T13: 0 | U13: 0 | V13: 1 | W13: 0 | X13: 0 | Y13: 0 | Z13: 0 | AA13: 0 | AB13: 1 | AC13: Yes | AD13: 0 | AE13: 1 | AF13: 0 | AG13: 0 | AH13: Yes | AK13: Yes | AL13: Yes | AM13: Yes | AN13: 2 hr | AO13: 0 | AP13: 1 | AQ13: 1 | AR13: 1 | AS13: 1 | AT13: 1 | AU13: 1 | AV13: 1 | AW13: 1 | AX13: 0 | AY13: 1 | AZ13: 0 | BA13: 1 | BB13: 0 | BC13: 0 | BD13: 0 | BE13: 1 | BF13: JSK Whatsapp School Whatsapp Letter | BG13: 1 | BH13: 1 | BI13: 1 | BJ13: 0 | BQ13: 3 | BX13: Yes | BY13: 1 | BZ13: 0 | CA13: 1 | CB13: 0 | CC13: 0 | CD13: Yes | CE13: 1 | CF13: 0 | CG13: 0 | CH13: 1 | CI13: 0 | CR13: 12 | CS13: =Qual_FreeText!Z13 -> DIKSHA, YouTube, WhatsApp, Attendance App. | CT13: =Qual_FreeText!X13 -> DIKSHA Courses, iGOT Courses. | CU13: 1 | CV13: 0 | CW13: =Qual_FreeText!M13 -> विषय आधारित प्रशिक्षण, अगस्त, सितम्बर और दिसम्बर में शैक्षिक संवाद में सहभागिता, जीवन कौशल प्रशिक्षण, TLM मेला, जनगणना में ड्यूटी आदि SIR ड्यूटी – लगभग 1 से 1.5 माह तक कार्य किया l | CY13: 1
A14: 13 | B14: Rahul Kumar | C14: Ashish Nigam | D14: Ujjain | E14: Female | F14: 46184 | G14: Maths | H14: 25 | I14: 0 | J14: 0 | K14: 0 | L14: 1 | M14: 0 | N14: 0 | O14: 0 | P14: 3 | Q14: 1 | R14: 1 | S14: 1 | T14: 0 | U14: 0 | V14: 0 | W14: 0 | X14: 0 | Y14: 0 | Z14: 0 | AA14: 1 | AB14: 0 | AC14: Not sure | AD14: 0 | AE14: 1 | AF14: 0 | AG14: 0 | AH14: Not sure | AL14: Yes | AM14: Yes | AN14: 1 hr | AO14: 0 | AP14: 1 | AQ14: 0 | AR14: 1 | AS14: 0 | AT14: 1 | AU14: 0 | AV14: 1 | AW14: 0 | AY14: 1 | AZ14: 0 | BA14: 1 | BB14: 0 | BC14: 0 | BD14: 1 | BE14: 0 | BF14: JSK Whatsapp | BG14: 1 | BH14: 0 | BI14: 0 | BJ14: 0 | BK14: Yes | BQ14: 1 | BX14: No | BY14: 0 | BZ14: 0 | CA14: 0 | CB14: 1 | CC14: 0 | CD14: No | CE14: 0 | CF14: 0 | CG14: 0 | CH14: 0 | CI14: 1 | CJ14: Yes | CK14: 0 | CL14: 0 | CM14: 0 | CN14: 0 | CO14: 0 | CP14: 0 | CR14: 13 | CS14: =Qual_FreeText!Z14 -> Diksha, Igot and Education portal | CT14: =Qual_FreeText!X14 -> PLC course, Mansikta Course on IGot on Karmyogi app | CU14: 1 | CV14: 1 | CW14: =Qual_FreeText!M14 -> Participated in Block level subject training, One CLSS in August 2025, one digital course has been completed in December 2025. | CY14: 1
A15: 14 | B15: Rahul Kumar | C15: Ashish Nigam | D15: Ujjain | E15: Female | F15: 46185 | G15: Science | H15: 25 | I15: 0 | J15: 0 | K15: 0 | L15: 0 | M15: 0 | N15: 1 | O15: 0 | P15: 4 | Q15: 1 | R15: 1 | S15: 0 | T15: 0 | U15: 0 | V15: 0 | W15: 0 | X15: 0 | Y15: 0 | Z15: 0 | AA15: 0 | AB15: 1 | AC15: Not sure | AD15: 0 | AE15: 0 | AF15: 0 | AG15: 1 | AL15: Yes | AM15: Not sure | AN15: 2 hr | AO15: 0 | AP15: 1 | AQ15: 0 | AR15: 1 | AS15: 1 | AT15: 0 | AU15: 0 | AV15: 0 | AW15: 0 | AY15: 0 | AZ15: 0 | BA15: 1 | BB15: 0 | BC15: 0 | BD15: 1 | BE15: 1 | BF15: JSK Whatsapp School Whatsapp | BG15: 1 | BH15: 1 | BI15: 0 | BJ15: 0 | BK15: Yes | BX15: No | BY15: 0 | BZ15: 0 | CA15: 0 | CB15: 1 | CC15: 0 | CJ15: No | CK15: 0 | CL15: 1 | CM15: 0 | CN15: 1 | CO15: 0 | CP15: 0 | CR15: 14 | CS15: =Qual_FreeText!Z15 -> Diksha and Igot | CT15: =Qual_FreeText!X15 -> PLC digital course | CU15: 1 | CV15: 1 | CW15: =Qual_FreeText!M15 -> Digital course - PLC Dec, Subject training - July 2025, other 5 Days training - February 2026 | CX15: 1 | CY15: 1
A16: 15 | B16: Rashmi Mishra | C16: Rajshree Behera | D16: Gwalior | E16: Male | F16: 46184 | G16: Social Science Sanskrit | H16: 25 | I16: 0 | J16: 0 | K16: 1 | L16: 0 | M16: 1 | N16: 0 | O16: 0 | P16: 6 | Q16: 1 | R16: 1 | S16: 1 | T16: 0 | U16: 0 | V16: 1 | W16: 0 | X16: 0 | Y16: 0 | Z16: 0 | AA16: 1 | AB16: 1 | AC16: Yes | AD16: 0 | AE16: 1 | AF16: 0 | AG16: 0 | AH16: Yes | AK16: Yes | AL16: Yes | AM16: No | AN16: 4-5 hrs | AO16: 0 | AP16: 1 | AQ16: 0 | AR16: 0 | AS16: 0 | AT16: 1 | AU16: 0 | AV16: 1 | AW16: 0 | AX16: 0 | AY16: 0 | AZ16: 0 | BA16: 1 | BB16: 0 | BC16: 0 | BD16: 1 | BE16: 0 | BF16: JSK Whatsapp | BG16: 1 | BH16: 0 | BI16: 0 | BJ16: 0 | BQ16: 2 | BX16: Yes | BY16: 0 | BZ16: 0 | CA16: 1 | CB16: 0 | CC16: 0 | CD16: Yes | CE16: 0 | CF16: 0 | CG16: 1 | CH16: 0 | CI16: 1 | CR16: 15 | CS16: =Qual_FreeText!Z16 -> DIKSHA and I GoT | CT16: =Qual_FreeText!X16 -> PLC and Karmyogi Course series | CU16: 1 | CV16: 1 | CW16: =Qual_FreeText!M16 -> Subject training (August), CLSS (November & December), I got training (Across the year), Tree plantation (Across the year), YTL ( September), | CX16: 1 | CY16: 1
A17: 16 | B17: Naushad Mirza | C17: Deeksha Singh | D17: Panna | E17: Male | F17: 46183 | G17: Maths | H17: 16 | I17: 0 | J17: 0 | K17: 0 | L17: 1 | M17: 0 | N17: 0 | O17: 0 | P17: 4 | Q17: 1 | R17: 1 | S17: 1 | T17: 1 | U17: 0 | V17: 0 | W17: 0 | X17: 0 | Y17: 0 | Z17: 1 | AA17: 0 | AB17: 0 | AC17: Yes | AD17: 0 | AE17: 1 | AF17: 0 | AG17: 0 | AH17: No | AI17: Not Sure | AL17: Yes | AM17: Not sure | AN17: 3 hr | AO17: 0 | AP17: 1 | AQ17: 0 | AR17: 0 | AS17: 0 | AT17: 0 | AU17: 0 | AV17: 0 | AW17: 0 | AX17: 1 | AY17: 1 | AZ17: 0 | BA17: 0 | BB17: 1 | BC17: 0 | BD17: 1 | BE17: 1 | BF17: JSK Whatsapp Letter Other | BG17: 1 | BH17: 0 | BI17: 1 | BJ17: 1 | BQ17: 3 | BR17: 0 | BS17: 1 | BT17: 1 | BU17: 1 | BV17: 0 | BW17: 0 | BX17: Couldn't remember particular learning from CLSS | BY17: 0 | BZ17: 0 | CA17: 1 | CB17: 0 | CC17: 0 | CD17: Yes | CE17: 0 | CF17: 1 | CG17: 0 | CH17: 0 | CI17: 0 | CR17: 16 | CS17: =Qual_FreeText!Z17 -> diksha app, whatsapp | CT17: =Qual_FreeText!X17 -> It was shared in the group, and the CAC has been consistently encouraging participants and sending timelymessages and nudges to support them in completing the courses. | CU17: 1 | CV17: 0 | CW17: =Qual_FreeText!M17 -> He shared that he participated in a three-day subject training conducted at the block level in Ajaygarh. He alsomentioned completing one or two digital courses; however, he was unable to recall the specifi c names or details ofthese courses. Additionally, he has attended CLSS as participants. | CX17: 1 | CY17: 1
A18: 17 | B18: Pushpendra Singh | C18: Krishna | D18: Rewa | E18: Female | F18: 46188 | G18: Hindi Social Science | H18: 22 | I18: 1 | J18: 0 | K18: 1 | L18: 0 | M18: 0 | N18: 0 | O18: 0 | P18: 4 | Q18: 1 | R18: 1 | S18: 1 | T18: 0 | U18: 0 | V18: 1 | W18: 0 | X18: 1 | Y18: 0 | Z18: 0 | AA18: 1 | AB18: 0 | AC18: Yes | AD18: 0 | AE18: 0 | AF18: 0 | AG18: 1 | AK18: Yes | AL18: Yes | AM18: Yes | AN18: 4-5 hrs | AO18: 0 | AP18: 1 | AQ18: 1 | AR18: 1 | AS18: 0 | AT18: 1 | AU18: 0 | AV18: 1 | AW18: 0 | AX18: 0 | AY18: 1 | AZ18: 0 | BA18: 1 | BB18: 0 | BC18: 0 | BD18: 0 | BE18: 0 | BF18: JSK Whatsapp | BG18: 1 | BH18: 0 | BI18: 0 | BJ18: 0 | BQ18: 3 | BR18: 1 | BS18: 0 | BT18: 1 | BU18: 1 | BV18: 0 | BW18: 0 | BX18: Couldn't remember particular learning from CLSS | BY18: 0 | BZ18: 0 | CA18: 1 | CB18: 0 | CC18: 0 | CD18: Yes | CE18: 0 | CF18: 0 | CG18: 0 | CH18: 0 | CI18: 1 | CR18: 17 | CS18: =Qual_FreeText!Z18 -> The teacher reported using DIKSHA, YouTube Live, and WhatsApp as online platforms for learning and accessing training-related information. | CT18: =Qual_FreeText!X18 -> The teacher reported completing courses on the DIKSHA platform during the last year but was unable to recall the exact course names. | CU18: 1 | CV18: 0 | CW18: =Qual_FreeText!M18 -> The teacher could not recall the exact dates and duration of participation. However, the teacher reported attending Subject Training, CLSS, Digital Training, YouTube Live sessions, follow-up activities, and DIKSHA courses during the academic year. | CX18: 1 | CY18: 1
A19: 18 | B19: Sonali Patidar | C19: Dilip Kag | D19: Harda | E19: Male | F19: 46185 | G19: Social Science Sanskrit | H19: 15 | I19: 0 | J19: 0 | K19: 1 | L19: 0 | M19: 1 | N19: 0 | O19: 0 | P19: 2 | Q19: 1 | R19: 0 | S19: 1 | T19: 1 | U19: 0 | V19: 0 | W19: 0 | X19: 0 | Y19: 0 | Z19: 1 | AA19: 0 | AB19: 1 | AC19: Yes | AD19: 1 | AE19: 1 | AF19: 1 | AG19: 0 | AH19: Yes | AI19: Yes | AL19: No | AN19: 1 hr | AO19: 1 | AP19: 1 | AQ19: 0 | BK19: Yes | BL19: 0 | BM19: 1 | BN19: 1 | BO19: 1 | BP19: 0 | BQ19: 4 | BR19: 1 | BS19: 1 | BT19: 1 | BU19: 0 | BV19: 1 | BW19: 0 | BX19: Yes | BY19: 1 | BZ19: 0 | CA19: 1 | CB19: 0 | CC19: 0 | CD19: Yes | CE19: 0 | CF19: 1 | CG19: 1 | CH19: 0 | CI19: 0 | CR19: 18 | CS19: =Qual_FreeText!Z19 -> 0 | CT19: =Qual_FreeText!X19 -> 0 | CU19: 0 | CV19: 1 | CW19: =Qual_FreeText!M19 -> ELIT प्रशिक्षण 2025, सामाजिक विज्ञान राज्य स्तरीय प्रशिक्षण 2025, CLSS अगस्त 2025 से नियमित, प्रशिक्षण उपरांत सीख की यात्रा , उमंग प्रशिक्षण 2025, जनगणना कार्य 2025-26 | CX19: 1 | CY19: 1
A20: 19 | B20: Rahul Kumar | C20: Ashish Nigam | D20: Neemuch | E20: Male | F20: 46188 | G20: Social Science | H20: 13 | I20: 0 | J20: 0 | K20: 1 | L20: 0 | M20: 0 | N20: 0 | O20: 0 | P20: 6 | Q20: 1 | R20: 1 | S20: 1 | T20: 0 | U20: 0 | V20: 0 | W20: 0 | X20: 1 | Y20: 0 | Z20: 0 | AA20: 1 | AB20: 0 | AC20: Not sure | AD20: 0 | AE20: 1 | AF20: 0 | AG20: 0 | AH20: Not sure | AL20: Yes | AM20: Yes | AN20: 2 hr | AO20: 1 | AP20: 1 | AQ20: 0 | AR20: 0 | AS20: 0 | AT20: 1 | AU20: 0 | AV20: 0 | AW20: 0 | AX20: 0 | AY20: 1 | AZ20: 0 | BA20: 1 | BB20: 0 | BC20: 0 | BD20: 0 | BE20: 0 | BF20: JSK Whatsapp School Whatsapp Letter | BG20: 1 | BH20: 1 | BI20: 1 | BJ20: 0 | BQ20: 4 | BR20: 1 | BS20: 0 | BT20: 1 | BU20: 0 | BV20: 0 | BW20: 0 | BX20: Yes | BY20: 1 | BZ20: 0 | CA20: 1 | CB20: 0 | CC20: 0 | CD20: No | CE20: 0 | CF20: 0 | CG20: 0 | CH20: 0 | CI20: 1 | CR20: 19 | CS20: =Qual_FreeText!Z20 -> Diksha App, I-GOT | CT20: =Qual_FreeText!X20 -> PLC and courses on Karmyogi | CU20: 1 | CV20: 1 | CW20: =Qual_FreeText!M20 -> Participated in all CLSS except last one, In person training- July 2025, Digital course - Jan 2026 | CX20: 1 | CY20: 1
A21: 20 | B21: Rajesh Solanki | C21: Jay Prakash | D21: Shivpuri | E21: Female | F21: 46188 | G21: Maths Science | H21: 24 | I21: 0 | J21: 0 | K21: 0 | L21: 1 | M21: 0 | N21: 1 | O21: 0 | P21: 6 | Q21: 1 | R21: 1 | S21: 1 | T21: 0 | U21: 0 | V21: 0 | W21: 0 | X21: 0 | Y21: 0 | Z21: 0 | AA21: 0 | AB21: 0 | AC21: Yes | AD21: 0 | AE21: 1 | AF21: 0 | AG21: 0 | AH21: Yes | AL21: Yes | AM21: Yes | AO21: 1 | AP21: 1 | AQ21: 0 | AR21: 1 | AS21: 1 | AT21: 0 | AU21: 0 | AV21: 0 | AW21: 0 | AX21: 0 | AY21: 0 | AZ21: 0 | BA21: 1 | BB21: 0 | BC21: 0 | BD21: 0 | BE21: 0 | BF21: JSK Whatsapp | BG21: 1 | BH21: 0 | BI21: 0 | BJ21: 0 | BQ21: 3 | BX21: Yes | BY21: 0 | BZ21: 0 | CA21: 1 | CB21: 0 | CC21: 0 | CD21: Yes | CE21: 1 | CF21: 0 | CG21: 0 | CH21: 0 | CI21: 0 | CR21: 20 | CS21: =Qual_FreeText!Z21 -> Diksha App, I-GOT | CT21: =Qual_FreeText!X21 -> AI, प्रिंट समृद्ध वातावरण, सिख एंड सहयोग, कर्मयोगी के कोर्से में भी भाग लिया था. | CU21: 1 | CV21: 0 | CW21: =Qual_FreeText!M21 -> मैंने 3 CLSS की चर्चा में भाग लिया था जिसमें हमने एक दुसरे के अनुभव से सीखना, पुस्तिका के आधार पर सभी के साथ चर्चा होती थी, किसी भी प्रकार के डिजिटल चीजों का ऊपयोग नहीं होता था. आपने बाद बताया की आपने 3 CLSS और हेल्थ वेलनेस कोर्स में भी भाग लिया था. | CY21: 1
A22: 21 | B22: Ritesh Pandey | C22: Naushad Mirza | D22: Chhindwara | E22: Male | F22: 46189 | G22: Maths Science | H22: 28 | I22: 0 | J22: 0 | K22: 0 | L22: 1 | M22: 0 | N22: 1 | O22: 0 | P22: 6 | Q22: 1 | R22: 0 | S22: 1 | T22: 0 | U22: 0 | V22: 1 | W22: 0 | X22: 0 | Y22: 0 | Z22: 0 | AA22: 0 | AB22: 0 | AC22: Yes | AD22: 0 | AE22: 0 | AF22: 0 | AG22: 1 | AK22: Yes | AL22: Yes | AM22: Yes | AN22: 2 hr | AO22: 0 | AP22: 1 | AQ22: 0 | BK22: Yes | BL22: 0 | BM22: 0 | BN22: 1 | BO22: 0 | BP22: 0 | BQ22: 3 | BR22: 0 | BS22: 0 | BT22: 0 | BU22: 0 | BV22: 1 | BW22: 0 | BX22: Couldn't remember particular learning from CLSS | BY22: 0 | BZ22: 0 | CA22: 0 | CB22: 1 | CC22: 0 | CD22: Yes | CE22: 0 | CF22: 0 | CG22: 0 | CH22: 0 | CI22: 1 | CR22: 21 | CS22: =Qual_FreeText!Z22 -> I GoT | CT22: =Qual_FreeText!X22 -> Karm Yogi | CU22: 0 | CV22: 1 | CW22: =Qual_FreeText!M22 -> 3 CLSS in diffiernt month on the basis of availibility of the teacher in school. 2 days Math and 2 days Science subject training at Block level. 2-3 times Youtube live attended. He also participated in JSK level Science exhibition. He also involved in Sansad khel pratiyogita. Participated in JSK level CAC Organized Samiksha meeting. | CY22: 1
A23: 22 | B23: Rashmi Mishra | C23: Vaibhav Tambe | D23: Datia | E23: Female | F23: 46188 | G23: Social Science | H23: 23 | I23: 0 | J23: 0 | K23: 1 | L23: 0 | M23: 0 | N23: 0 | O23: 0 | P23: 6 | Q23: 1 | R23: 1 | S23: 1 | T23: 0 | U23: 0 | V23: 0 | W23: 0 | X23: 0 | Y23: 0 | Z23: 0 | AA23: 1 | AB23: 1 | AC23: Yes | AD23: 0 | AE23: 1 | AF23: 0 | AG23: 0 | AH23: No | AL23: Yes | AM23: Yes | AN23: 2 hr | AO23: 0 | AP23: 1 | AQ23: 0 | AR23: 0 | AS23: 0 | AT23: 1 | AU23: 0 | AV23: 1 | AW23: 1 | AX23: 0 | AY23: 1 | AZ23: 0 | BA23: 0 | BB23: 0 | BC23: 0 | BD23: 0 | BE23: 0 | BF23: JSK Whatsapp | BG23: 1 | BH23: 0 | BI23: 0 | BJ23: 0 | BQ23: 5 | BR23: 1 | BS23: 0 | BT23: 0 | BU23: 0 | BV23: 0 | BW23: 0 | BX23: Yes | BY23: 0 | BZ23: 0 | CA23: 0 | CB23: 0 | CC23: 1 | CD23: Yes | CE23: 0 | CF23: 0 | CG23: 0 | CH23: 0 | CI23: 1 | CR23: 22 | CS23: =Qual_FreeText!Z23 -> DIKSHA | CT23: =Qual_FreeText!X23 -> बहुविधि शिक्षण और बहुविधि अभिव्यक्ति | CU23: 1 | CV23: 0 | CW23: =Qual_FreeText!M23 -> Shaishik Samvaad, Subject Traning, DIgital Traning, Jangana (Cencus Duty) BRC Meetings | CY23: 1
A24: 23 | B24: Rashmi Mishra | C24: Vaibhav Tambe | D24: Datia | E24: Male | F24: 46189 | G24: Maths | H24: 10 | I24: 0 | J24: 0 | K24: 0 | L24: 1 | M24: 0 | N24: 0 | O24: 0 | P24: 5 | Q24: 1 | R24: 1 | S24: 1 | T24: 0 | U24: 0 | V24: 0 | W24: 0 | X24: 0 | Y24: 0 | Z24: 0 | AA24: 1 | AB24: 1 | AC24: Yes | AD24: 0 | AE24: 1 | AF24: 0 | AG24: 0 | AH24: No | AL24: Yes | AM24: No | AN24: 4-5 hrs | AO24: 0 | AP24: 1 | AQ24: 0 | AR24: 0 | AS24: 0 | AT24: 0 | AU24: 0 | AV24: 0 | AW24: 0 | AX24: 1 | AY24: 1 | AZ24: 0 | BA24: 0 | BB24: 0 | BC24: 0 | BD24: 0 | BE24: 0 | BF24: JSK Whatsapp | BG24: 1 | BH24: 0 | BI24: 0 | BJ24: 0 | BQ24: 5 | BR24: 0 | BS24: 0 | BT24: 0 | BU24: 0 | BV24: 0 | BW24: 1 | BX24: Yes | BY24: 1 | BZ24: 0 | CA24: 0 | CB24: 0 | CC24: 0 | CD24: No | CE24: 0 | CF24: 0 | CG24: 0 | CH24: 0 | CI24: 1 | CR24: 23 | CS24: =Qual_FreeText!Z24 -> DIKSHA | CT24: =Qual_FreeText!X24 -> Teacher not able to recall course name | CU24: 1 | CV24: 0 | CW24: =Qual_FreeText!M24 -> Participated in Subject Training, Digital Training, CLSS (Aug, Dec), and election-related duties during the 2025–26 academic year; no other activities were mentioned. | CY24: 1
A25: 24 | B25: Vaibhav Kurwade | C25: Anjali | D25: Narsinghpur | E25: Male | F25: 46188 | G25: Social Science Sanskrit | H25: 43 | I25: 0 | J25: 0 | K25: 1 | L25: 0 | M25: 1 | N25: 0 | O25: 0 | P25: 2 | Q25: 1 | R25: 1 | S25: 1 | T25: 0 | U25: 0 | V25: 1 | W25: 0 | X25: 0 | Y25: 0 | Z25: 0 | AA25: 0 | AB25: 0 | AC25: Yes | AD25: 0 | AE25: 1 | AF25: 0 | AG25: 0 | AH25: No | AK25: Yes | AL25: Yes | AM25: Yes | AN25: 3 hr | AO25: 0 | AP25: 1 | AQ25: 0 | AR25: 1 | AS25: 0 | AT25: 0 | AU25: 0 | AV25: 1 | AW25: 0 | AX25: 0 | AY25: 0 | AZ25: 0 | BA25: 1 | BB25: 0 | BC25: 0 | BD25: 0 | BE25: 0 | BF25: JSK Whatsapp Letter | BG25: 1 | BH25: 0 | BI25: 1 | BJ25: 0 | BQ25: 1 | BR25: 0 | BS25: 0 | BT25: 0 | BU25: 0 | BV25: 0 | BW25: 1 | BX25: Couldn't remember particular learning from CLSS | BY25: 1 | BZ25: 1 | CA25: 0 | CB25: 0 | CC25: 0 | CD25: Yes | CE25: 0 | CF25: 0 | CG25: 0 | CH25: 0 | CI25: 1 | CR25: 24 | CS25: =Qual_FreeText!Z25 -> DIKSHA and IGOT | CT25: =Qual_FreeText!X25 -> not able to recall | CU25: 1 | CV25: 1 | CW25: =Qual_FreeText!M25 -> CLSS in July, YTL, Digital training, subject training- (not remember the exact time), | CY25: 1
A26: 25 | B26: Rahul Kumar | C26: Devendra Sharma | D26: Ujjain | E26: Female | F26: 46182 | G26: Social Science | H26: 18 | I26: 0 | J26: 0 | K26: 1 | L26: 0 | M26: 0 | N26: 0 | O26: 0 | P26: 4 | Q26: 1 | R26: 1 | S26: 1 | T26: 0 | U26: 0 | V26: 1 | W26: 0 | X26: 0 | Y26: 0 | Z26: 0 | AA26: 0 | AB26: 0 | AC26: Yes | AD26: 0 | AE26: 1 | AF26: 0 | AG26: 1 | AH26: Not sure | AK26: Not Sure | AL26: Yes | AM26: Yes | AN26: 3 hr | AO26: 0 | AP26: 1 | AQ26: 0 | AR26: 0 | AS26: 1 | AT26: 0 | AU26: 1 | AV26: 0 | AW26: 0 | AX26: 0 | AY26: 0 | AZ26: 0 | BA26: 1 | BB26: 0 | BC26: 0 | BD26: 0 | BE26: 0 | BF26: JSK Whatsapp | BG26: 1 | BH26: 0 | BI26: 0 | BJ26: 0 | BQ26: 1 | BR26: 0 | BS26: 0 | BT26: 0 | BU26: 0 | BV26: 0 | BW26: 1 | BX26: Couldn't remember particular learning from CLSS | BY26: 0 | BZ26: 1 | CA26: 0 | CB26: 0 | CC26: 0 | CD26: No | CE26: 0 | CF26: 0 | CG26: 0 | CH26: 0 | CI26: 1 | CR26: 25 | CS26: =Qual_FreeText!Z26 -> courses on Karmyogi app/DIKSHA | CT26: =Qual_FreeText!X26 -> RSK | CU26: 1 | CV26: 0 | CW26: =Qual_FreeText!M26 -> The teacher participated in the following professional development activities: Subject-Specific Training (July 2025), CLSS (September 2025), and the PLC Course (January 2026). | CY26: 1
A27: 26 | B27: Dilip Kag | C27: Sonali Patidar | D27: Dhar | E27: Female | F27: 46189 | G27: English Science | H27: 28 | I27: 0 | J27: 1 | K27: 0 | L27: 0 | M27: 0 | N27: 1 | O27: 0 | P27: 4 | Q27: 1 | R27: 1 | S27: 1 | T27: 0 | U27: 0 | V27: 0 | W27: 0 | X27: 0 | Y27: 0 | Z27: 0 | AA27: 1 | AB27: 0 | AC27: Yes | AD27: 0 | AE27: 1 | AF27: 0 | AG27: 0 | AH27: Yes | AL27: No | AN27: 1 hr | AO27: 0 | AP27: 1 | AQ27: 0 | AR27: 1 | AS27: 0 | AT27: 0 | AU27: 1 | AV27: 0 | AW27: 0 | AX27: 0 | AY27: 0 | AZ27: 0 | BA27: 1 | BB27: 0 | BC27: 0 | BD27: 0 | BE27: 0 | BF27: JSK Whatsapp | BG27: 1 | BH27: 0 | BI27: 0 | BJ27: 0 | BQ27: 4 | BR27: 1 | BS27: 1 | BT27: 0 | BU27: 1 | BV27: 1 | BW27: 0 | BX27: Yes | BY27: 0 | BZ27: 0 | CA27: 1 | CB27: 0 | CC27: 0 | CD27: Yes | CE27: 1 | CF27: 1 | CG27: 0 | CH27: 0 | CI27: 0 | CR27: 26 | CS27: =Qual_FreeText!Z27 -> 0 | CT27: =Qual_FreeText!X27 -> 0 | CU27: 0 | CV27: 0 | CW27: =Qual_FreeText!M27 -> शैक्षिक संवाद अगस्त, सितम्बर, दिसंबर, जनवरी
A28: 27 | B28: Vaibhav Kurwade | C28: Anjali | D28: Jabalpur | E28: Female | F28: 46189 | G28: English Social Science | H28: 16 | I28: 0 | J28: 1 | K28: 1 | L28: 0 | M28: 0 | N28: 0 | O28: 0 | P28: 1 | Q28: 1 | R28: 0 | S28: 1 | T28: 0 | U28: 0 | V28: 0 | W28: 0 | X28: 1 | Y28: 0 | Z28: 0 | AA28: 1 | AB28: 0 | AC28: Yes | AD28: 0 | AE28: 1 | AF28: 0 | AG28: 0 | AH28: Not sure | AL28: No | AN28: 1 hr | AO28: 1 | AP28: 0 | AQ28: 0 | BK28: Yes | BL28: 1 | BM28: 0 | BN28: 0 | BO28: 1 | BP28: 0 | BQ28: 1 | BR28: 0 | BS28: 0 | BT28: 0 | BU28: 0 | BV28: 0 | BW28: 1 | BX28: Couldn't remember particular learning from CLSS | BY28: 0 | BZ28: 0 | CA28: 0 | CB28: 1 | CC28: 0 | CD28: Yes | CE28: 1 | CF28: 0 | CG28: 0 | CH28: 1 | CI28: 0 | CR28: 27 | CS28: =Qual_FreeText!Z28 -> 0 | CT28: =Qual_FreeText!X28 -> 0 | CU28: 0 | CV28: 0 | CW28: =Qual_FreeText!M28 -> Subject Training– April/May, CLSS – 1 session, JSK Meeting – Monthly, SIR – November
A29: 28 | B29: Pushpendra Singh | C29: Krishna | D29: Rewa | E29: Male | F29: 46189 | G29: Maths Science | H29: 19 | I29: 0 | J29: 0 | K29: 0 | L29: 1 | M29: 0 | N29: 1 | O29: 0 | P29: 7 | Q29: 1 | R29: 0 | S29: 1 | T29: 0 | U29: 0 | V29: 0 | W29: 0 | X29: 1 | Y29: 0 | Z29: 0 | AA29: 1 | AB29: 0 | AC29: Yes | AD29: 1 | AE29: 1 | AF29: 0 | AG29: 0 | AH29: Yes | AL29: No | AO29: 1 | AP29: 0 | AQ29: 0 | BK29: Yes | BL29: 1 | BM29: 0 | BN29: 0 | BO29: 1 | BP29: 0 | BQ29: 3 | BR29: 1 | BS29: 1 | BT29: 0 | BU29: 1 | BV29: 0 | BW29: 0 | BX29: Yes | BY29: 0 | BZ29: 0 | CA29: 1 | CB29: 0 | CC29: 0 | CD29: Yes | CE29: 1 | CF29: 1 | CG29: 0 | CH29: 0 | CI29: 0 | CR29: 28 | CS29: =Qual_FreeText!Z29 -> 0 | CT29: =Qual_FreeText!X29 -> 0 | CU29: 0 | CV29: 0 | CW29: =Qual_FreeText!M29 -> During the academic year, the teacher participated in Mathematics MT Training and attended CLSS sessions for Class 3 in August, September, and December
A30: 29 | B30: Rashmi Mishra | C30: Vaibhav Tambe | D30: Datia | E30: Male | F30: 46190 | G30: Hindi Social Science | H30: 26 | I30: 1 | J30: 0 | K30: 1 | L30: 0 | M30: 0 | N30: 0 | O30: 0 | P30: 5 | Q30: 1 | R30: 1 | S30: 1 | T30: 0 | U30: 0 | V30: 0 | W30: 0 | X30: 0 | Y30: 0 | Z30: 0 | AA30: 0 | AB30: 0 | AC30: Yes | AD30: 0 | AE30: 1 | AF30: 0 | AG30: 0 | AH30: No | AL30: Yes | AM30: No | AN30: 2 hr | AO30: 0 | AP30: 1 | AQ30: 0 | AR30: 0 | AS30: 0 | AT30: 0 | AU30: 0 | AV30: 1 | AW30: 0 | AX30: 0 | AY30: 0 | AZ30: 0 | BA30: 1 | BB30: 0 | BC30: 0 | BD30: 0 | BE30: 0 | BF30: JSK Whatsapp | BG30: 1 | BH30: 0 | BI30: 0 | BJ30: 0 | BQ30: 4 | BR30: 1 | BS30: 1 | BT30: 1 | BU30: 0 | BV30: 0 | BW30: 0 | BX30: Yes | BY30: 1 | BZ30: 0 | CA30: 0 | CB30: 0 | CC30: 0 | CD30: Yes | CE30: 0 | CF30: 0 | CG30: 0 | CH30: 1 | CI30: 0 | CR30: 29 | CS30: =Qual_FreeText!Z30 -> DIKSHA | CT30: =Qual_FreeText!X30 -> Shaishik Samwaad: Sath Sahyog aur SIkh | CU30: 1 | CV30: 0 | CW30: =Qual_FreeText!M30 -> Subject Training, CLSS, Digital Training. | CY30: 1
A31: 30 | B31: Ritesh Pandey | C31: Other | D31: Chhindwara | E31: Female | F31: 46191 | G31: Maths | H31: 15 | I31: 0 | J31: 0 | K31: 0 | L31: 1 | M31: 0 | N31: 0 | O31: 0 | P31: 1 | Q31: 1 | R31: 1 | S31: 1 | T31: 0 | U31: 0 | V31: 0 | W31: 0 | X31: 0 | Y31: 0 | Z31: 0 | AA31: 0 | AB31: 1 | AC31: Yes | AD31: 0 | AE31: 1 | AF31: 0 | AG31: 0 | AH31: Not sure | AL31: Yes | AM31: Yes | AN31: 3 hr | AO31: 1 | AP31: 0 | AQ31: 0 | AR31: 1 | AS31: 1 | AT31: 1 | AU31: 0 | AV31: 1 | AW31: 0 | AX31: 0 | AY31: 1 | AZ31: 0 | BA31: 1 | BB31: 1 | BC31: 0 | BD31: 0 | BE31: 0 | BF31: JSK Whatsapp Letter | BG31: 1 | BH31: 0 | BI31: 1 | BJ31: 0 | BQ31: 5 | BR31: 0 | BS31: 0 | BT31: 0 | BU31: 0 | BV31: 0 | BW31: 1 | BX31: Yes | BY31: 0 | BZ31: 0 | CA31: 0 | CB31: 0 | CC31: 1 | CD31: Yes | CE31: 0 | CF31: 1 | CG31: 0 | CH31: 0 | CI31: 1 | CR31: 30 | CS31: =Qual_FreeText!Z31 -> DIksha, Igot | CT31: =Qual_FreeText!X31 -> Karmyogi, Shaikshik Smavad | CU31: 1 | CV31: 1 | CW31: =Qual_FreeText!M31 -> 5 ClSS in all month, she couldnt recall month name. | CY31: 1
A32: 31 | B32: Srujan Deshpande | C32: Devendra Sharma | D32: Shajapur | E32: Female | F32: 46185 | G32: Maths Science | H32: 20 | I32: 0 | J32: 0 | K32: 0 | L32: 1 | M32: 0 | N32: 1 | O32: 0 | P32: 3 | Q32: 1 | R32: 1 | S32: 1 | T32: 0 | U32: 0 | V32: 1 | W32: 0 | X32: 0 | Y32: 0 | Z32: 1 | AA32: 0 | AB32: 0 | AC32: Yes | AD32: 1 | AE32: 1 | AF32: 0 | AG32: 0 | AH32: Yes | AK32: Not Sure | AL32: Yes | AM32: Yes | AN32: 3 hr | AO32: 0 | AP32: 1 | AQ32: 0 | AR32: 1 | AS32: 1 | AT32: 1 | AU32: 1 | AV32: 1 | AW32: 1 | AX32: 0 | AY32: 0 | AZ32: 0 | BA32: 1 | BB32: 0 | BC32: 0 | BD32: 0 | BE32: 0 | BF32: JSK Whatsapp Letter | BG32: 1 | BH32: 0 | BI32: 1 | BJ32: 0 | BQ32: 4 | BR32: 1 | BS32: 1 | BT32: 1 | BU32: 0 | BV32: 1 | BW32: 0 | BX32: Yes | BY32: 0 | BZ32: 0 | CA32: 1 | CB32: 0 | CC32: 0 | CD32: Yes | CE32: 0 | CF32: 0 | CG32: 0 | CH32: 0 | CI32: 1 | CR32: 31 | CS32: =Qual_FreeText!Z32 -> Diksha, iGot कर्मयोगी | CT32: =Qual_FreeText!X32 -> शैक्षिक संवाद, बहुविधि शिक्षण, AI, classroom managment | CU32: 1 | CV32: 1 | CW32: =Qual_FreeText!M32 -> विषय प्रशिक्षण (2025-26), CLSS सत्र (सभी), DIKSHA पाठ्यक्रम एवं विभागीय ऑनलाइन प्रशिक्षण (2 सप्ताह मे 4-6 घंटे)। | CY32: 1
A33: 32 | B33: Srujan Deshpande | C33: Devendra Sharma | D33: Shajapur | E33: Female | F33: 46186 | G33: Maths Science | H33: 22 | I33: 0 | J33: 0 | K33: 0 | L33: 1 | M33: 0 | N33: 1 | O33: 0 | P33: 6 | Q33: 1 | R33: 0 | S33: 1 | T33: 0 | U33: 0 | V33: 1 | W33: 0 | X33: 0 | Y33: 0 | Z33: 0 | AA33: 0 | AB33: 1 | AC33: Yes | AD33: 0 | AE33: 1 | AF33: 0 | AG33: 0 | AH33: Yes | AK33: Yes | AL33: Yes | AM33: Yes | AN33: 2 hr | AO33: 0 | AP33: 1 | AQ33: 1 | BL33: 0 | BM33: 0 | BN33: 1 | BO33: 0 | BP33: 0 | BQ33: 5 | BR33: 0 | BS33: 0 | BT33: 0 | BU33: 0 | BV33: 0 | BW33: 1 | BX33: Couldn't remember particular learning from CLSS | BY33: 0 | BZ33: 1 | CA33: 0 | CB33: 0 | CC33: 0 | CD33: Yes | CE33: 0 | CF33: 0 | CG33: 0 | CH33: 0 | CI33: 1 | CR33: 32 | CS33: =Qual_FreeText!Z33 -> Diksha, कर्मयोगी | CT33: =Qual_FreeText!X33 -> तत्काल याद नहीं आए किन्तु कोर्स किए है। | CU33: 1 | CV33: 0 | CW33: =Qual_FreeText!M33 -> विषय प्रशिक्षण (विज्ञान एवं गणित), CLSS (5 सत्र), YTL ऑनलाइन सत्र, जनगणना कार्य। | CY33: 1
A34: 33 | B34: Srujan Deshpande | C34: Devendra Sharma | D34: Dewas | E34: Male | F34: 46188 | G34: Maths | H34: 20 | I34: 0 | J34: 0 | K34: 0 | L34: 1 | M34: 0 | N34: 0 | O34: 0 | P34: 1 | Q34: 1 | R34: 1 | S34: 1 | T34: 0 | U34: 0 | V34: 0 | W34: 0 | X34: 0 | Y34: 1 | Z34: 0 | AA34: 1 | AB34: 0 | AC34: Yes | AD34: 0 | AE34: 1 | AF34: 0 | AG34: 0 | AH34: Yes | AL34: Yes | AM34: Yes | AN34: 3 hr | AO34: 0 | AP34: 1 | AQ34: 1 | AR34: 1 | AS34: 1 | AT34: 1 | AU34: 1 | AV34: 0 | AW34: 0 | AX34: 0 | AY34: 0 | AZ34: 0 | BA34: 1 | BB34: 0 | BC34: 0 | BD34: 0 | BE34: 0 | BF34: JSK Whatsapp Letter | BG34: 1 | BH34: 0 | BI34: 1 | BJ34: 0 | BQ34: 5 | BR34: 1 | BS34: 0 | BT34: 0 | BU34: 0 | BV34: 0 | BW34: 0 | BX34: Yes | BY34: 0 | BZ34: 1 | CA34: 0 | CB34: 0 | CC34: 0 | CD34: Yes | CE34: 0 | CF34: 0 | CG34: 0 | CH34: 0 | CI34: 1 | CR34: 33 | CS34: =Qual_FreeText!Z34 -> याद नहीं है | CT34: =Qual_FreeText!X34 -> दीक्षा के कोर्स किए है | CU34: 0 | CV34: 0 | CW34: =Qual_FreeText!M34 -> वर्ष 2025-26 के दौरान विषय प्रशिक्षण 3 दिवसीय , PLC/CLSS (20-25 घंटे), DIKSHA डिजिटल कोर्स (4 घंटे) एवं अन्य ऑनलाइन प्रशिक्षणों में भागीदारी की (7-10 घंटे)। | CY34: 1
A35: 34 | B35: Srujan Deshpande | C35: Dilip Kag | D35: Ratlam | E35: Male | F35: 46191 | G35: Hindi Social Science | H35: 28 | I35: 1 | J35: 0 | K35: 1 | L35: 0 | M35: 0 | N35: 0 | O35: 0 | P35: 6 | Q35: 1 | R35: 0 | S35: 1 | T35: 0 | U35: 0 | V35: 0 | W35: 0 | X35: 0 | Y35: 0 | Z35: 0 | AA35: 0 | AB35: 1 | AC35: Yes | AD35: 0 | AE35: 1 | AF35: 0 | AG35: 0 | AH35: No | AL35: No | AO35: 0 | AP35: 1 | AQ35: 0 | BK35: Yes | BL35: 1 | BM35: 1 | BN35: 1 | BO35: 1 | BP35: 0 | BQ35: 4 | BR35: 0 | BS35: 0 | BT35: 0 | BU35: 0 | BV35: 0 | BW35: 1 | BX35: Couldn't remember particular learning from CLSS | BY35: 0 | BZ35: 0 | CA35: 0 | CB35: 1 | CC35: 0 | CD35: Yes | CE35: 0 | CF35: 0 | CG35: 0 | CH35: 0 | CI35: 1 | CR35: 34 | CS35: =Qual_FreeText!Z35 -> 0 | CT35: =Qual_FreeText!X35 -> 0 | CU35: 0 | CV35: 0 | CW35: =Qual_FreeText!M35 -> Social Science Subject Training (Piploda) – 2025-26, CLSS – Monthly, Deworming Training – One day, Science Model Exhibition – 2025-26
A36: 35 | B36: Deeksha Singh | C36: Dharmendra Mishra | D36: Chhatarpur | E36: Male | F36: 46192 | G36: Maths Science | H36: 13 | I36: 0 | J36: 0 | K36: 0 | L36: 1 | M36: 0 | N36: 1 | O36: 0 | P36: 6 | Q36: 1 | R36: 1 | S36: 1 | T36: 1 | U36: 0 | V36: 0 | W36: 0 | X36: 0 | Y36: 0 | Z36: 0 | AA36: 0 | AB36: 1 | AC36: Yes | AD36: 0 | AE36: 0 | AF36: 0 | AG36: 1 | AI36: Not Sure | AL36: Yes | AM36: Yes | AN36: 2 hr | AO36: 0 | AP36: 1 | AQ36: 0 | AR36: 0 | AS36: 0 | AT36: 0 | AU36: 0 | AV36: 0 | AW36: 0 | AX36: 1 | AY36: 1 | AZ36: 1 | BA36: 1 | BB36: 1 | BC36: 0 | BD36: 1 | BE36: 0 | BF36: JSK Whatsapp | BG36: 1 | BH36: 0 | BI36: 0 | BJ36: 0 | BQ36: 5 | BR36: 1 | BS36: 0 | BT36: 0 | BU36: 1 | BV36: 1 | BW36: 0 | BX36: Yes | BY36: 0 | BZ36: 0 | CA36: 0 | CB36: 1 | CC36: 0 | CD36: Yes | CE36: 0 | CF36: 0 | CG36: 0 | CH36: 0 | CI36: 1 | CR36: 35 | CS36: =Qual_FreeText!Z36 -> IGOT Karmyogi App, Diksha Courses | CT36: =Qual_FreeText!X36 -> बाल सुधार, महिलाओं की सुरक्षा, शैक्षणिक अधिगम | CU36: 1 | CV36: 1 | CW36: =Qual_FreeText!M36 -> CLSS 5(Aug to Dec) , Math, Science training 2 days(July), Igot Karmyogi app पर प्रशिक्षण लिया है, Apaar ID और जनगणना की ट्रेनिंग में पार्टिसिपेट | CY36: 1
A37: 36 | B37: Ritesh Pandey | C37: Other | D37: Chhindwara | E37: Male | F37: 46192 | G37: Maths | H37: 12 | I37: 0 | J37: 0 | K37: 0 | L37: 1 | M37: 0 | N37: 0 | O37: 0 | P37: 6 | Q37: 1 | R37: 1 | S37: 1 | T37: 0 | U37: 0 | V37: 0 | W37: 0 | X37: 1 | Y37: 0 | Z37: 0 | AA37: 0 | AB37: 1 | AC37: Yes | AD37: 0 | AE37: 0 | AF37: 0 | AG37: 1 | AL37: Yes | AM37: Not sure | AN37: 4-5 hrs | AO37: 0 | AP37: 1 | AQ37: 0 | AR37: 0 | AS37: 0 | AT37: 0 | AU37: 0 | AV37: 0 | AW37: 0 | AX37: 1 | AY37: 1 | AZ37: 0 | BA37: 0 | BB37: 0 | BC37: 0 | BD37: 0 | BE37: 0 | BF37: JSK Whatsapp School Whatsapp Letter | BG37: 1 | BH37: 1 | BI37: 1 | BJ37: 0 | BQ37: 3 | BR37: 0 | BS37: 0 | BT37: 0 | BU37: 0 | BV37: 0 | BW37: 1 | BX37: Yes | BY37: 0 | BZ37: 0 | CA37: 1 | CB37: 0 | CC37: 0 | CD37: Yes | CE37: 0 | CF37: 0 | CG37: 0 | CH37: 0 | CI37: 1 | CR37: 36 | CS37: =Qual_FreeText!Z37 -> Igot | CT37: =Qual_FreeText!X37 -> 12 | CU37: 0 | CV37: 1 | CW37: =Qual_FreeText!M37 -> It is mentioned, timeline was not told. | CY37: 1
A38: 37 | B38: Deeksha Singh | C38: Dharmendra Mishra | D38: Chhatarpur | E38: Male | F38: 46193 | G38: Social Science Sanskrit | H38: 16 | I38: 0 | J38: 0 | K38: 1 | L38: 0 | M38: 1 | N38: 0 | O38: 0 | P38: 6 | Q38: 1 | R38: 1 | S38: 1 | T38: 0 | U38: 0 | V38: 1 | W38: 0 | X38: 0 | Y38: 0 | Z38: 0 | AA38: 0 | AB38: 1 | AC38: Yes | AD38: 0 | AE38: 0 | AF38: 0 | AG38: 1 | AK38: Yes | AL38: Yes | AM38: Yes | AN38: 2 hr | AO38: 1 | AP38: 1 | AQ38: 0 | AR38: 0 | AS38: 0 | AT38: 0 | AU38: 0 | AV38: 0 | AW38: 0 | AX38: 1 | AY38: 0 | AZ38: 0 | BA38: 1 | BB38: 0 | BC38: 0 | BD38: 0 | BE38: 0 | BF38: JSK Whatsapp | BG38: 1 | BH38: 0 | BI38: 0 | BJ38: 0 | BQ38: 2 | BR38: 0 | BS38: 0 | BT38: 0 | BU38: 0 | BV38: 0 | BW38: 1 | BX38: Couldn't remember particular learning from CLSS | BY38: 0 | BZ38: 0 | CA38: 0 | CB38: 1 | CC38: 0 | CD38: Yes | CE38: 0 | CF38: 0 | CG38: 0 | CH38: 0 | CI38: 1 | CR38: 37 | CS38: =Qual_FreeText!Z38 -> IGOT | CT38: =Qual_FreeText!X38 -> पोस्को एक्ट, मादक पदार्थों से रिलेटेड कोर्स, NEP से रिलेटेड कोर्स IGOT ऐप पर | CU38: 0 | CV38: 1 | CW38: =Qual_FreeText!M38 -> CLSS -2, Subject Training -2day, YTL-1, IGOT पर लगभग 70 घंटे की ट्रेनिंग, दीक्षा ऐप पर शिक्षक संशय में थे। | CY38: 1
A39: 38 | B39: Srujan Deshpande | C39: Devendra Sharma | D39: Dewas | E39: Male | F39: 46189 | G39: Science | H39: 11 | I39: 0 | J39: 0 | K39: 0 | L39: 0 | M39: 0 | N39: 1 | O39: 0 | P39: 4 | Q39: 1 | R39: 1 | S39: 1 | T39: 0 | U39: 0 | V39: 1 | W39: 0 | X39: 0 | Y39: 1 | Z39: 1 | AA39: 0 | AB39: 0 | AC39: Yes | AD39: 0 | AE39: 1 | AF39: 0 | AG39: 0 | AH39: Yes | AK39: Yes | AL39: Yes | AM39: Yes | AN39: 3 hr | AO39: 0 | AP39: 1 | AQ39: 0 | AR39: 1 | AS39: 1 | AT39: 1 | AU39: 1 | AV39: 0 | AW39: 0 | AX39: 0 | AY39: 0 | AZ39: 0 | BA39: 1 | BB39: 0 | BC39: 0 | BD39: 0 | BE39: 0 | BF39: JSK Whatsapp Letter | BG39: 1 | BH39: 0 | BI39: 1 | BJ39: 0 | BQ39: Not Participated | BX39: Couldn't remember particular learning from CLSS | BY39: 0 | BZ39: 0 | CA39: 0 | CB39: 1 | CC39: 0 | CD39: Yes | CE39: 0 | CF39: 0 | CG39: 0 | CH39: 0 | CI39: 1 | CR39: 38 | CS39: =Qual_FreeText!Z39 -> Diksha | CT39: =Qual_FreeText!X39 -> याद नहीं है। | CU39: 1 | CV39: 0 | CW39: =Qual_FreeText!M39 -> NEP 20 प्रशिक्षण, विषय प्रशिक्षण, दीक्षा प्लेटफॉर्म के प्रशिक्षण एवं YTL गतिविधियों में वर्ष 2025-26 के दौरान सहभागिता। | CY39: 1
A40: 39 | B40: Ritesh Pandey | C40: Other | D40: Seoni | E40: Female | F40: 46193 | G40: Maths Science | H40: 3 | I40: 0 | J40: 0 | K40: 0 | L40: 1 | M40: 0 | N40: 1 | O40: 0 | P40: 6 | Q40: 1 | R40: 0 | S40: 1 | T40: 0 | U40: 0 | V40: 0 | W40: 0 | X40: 0 | Y40: 0 | Z40: 0 | AA40: 0 | AB40: 1 | AC40: Yes | AD40: 0 | AE40: 0 | AF40: 0 | AG40: 1 | AL40: Yes | AM40: Yes | AN40: 2 hr | AO40: 0 | AP40: 1 | AQ40: 0 | BK40: Yes | BL40: 0 | BM40: 0 | BN40: 0 | BO40: 1 | BP40: 0 | BQ40: 5 | BR40: 0 | BS40: 0 | BT40: 0 | BU40: 0 | BV40: 0 | BW40: 1 | BX40: Yes | BY40: 0 | BZ40: 0 | CA40: 0 | CB40: 0 | CC40: 1 | CD40: Yes | CE40: 0 | CF40: 0 | CG40: 0 | CH40: 0 | CI40: 1 | CR40: 39 | CS40: =Qual_FreeText!Z40 -> Igot | CT40: =Qual_FreeText!X40 -> Karmyogi | CU40: 0 | CV40: 1 | CW40: =Qual_FreeText!M40 -> She couldn't mention but did mention about subject training and CLSS. | CY40: 1
...

Sheet Sheet1
A1: Annual Enagement | D1: Look for the other activities participated by teachers in the qualitative data set
A2: Subject Training | B2: 56
A3: Digital Training | B3: 40
A4: CLSS | B4: 53
A5: SKG | B5: 9
A6: Webex | B6: 1
A7: YTL | B7: 21
A8: APF Demo Sessions | B8: 0
A9: SIR | B9: 9
A10: Muskaan Dreams- DIET Training | B10: 2
A11: HM Training | B11: 7
A12: Election related Duties | B12: 17
A13: Any other | B13: 26

Sheet Qual_FreeText
A1: Teacher_ID | B1: Name of the interviewer | C1: Name of the note-taker | D1: District of respondent teacher | E1: Gender of respondent | F1: Date of the interview | G1: Subject taught by teacher | H1: Years of teaching experience | I1: Teachers Academic Responsibilities in a Day | J1: Teachers non-academic responsibilities in a Day | K1: Key response note on teacher's daily engagement | L1: Activities participated over 2025-26 academic year | M1: List all the participated activities with timeline such as CLSS Aug, Dec | N1: Key response notes on teacher's annual engagement | O1: Key feedback to improve training session design or in-person training in general | P1: Training resources received from in-person training | Q1: Name of the material__lesson plan or strategy teacher tried using in class- | R1: Key feedback__response on training material and resources | S1: Examples of classroom implementation of any topic__ plan or material | T1: Key response note on teachers' experience with follow-up activities. | U1: Reasons for finding particular follow-up activity useful or not useful | V1: Are there any challenges which might limit teachers participation in online discussion calls | W1: Post in person training or follow up calls, what makes classroom implementation difficult | X1: Name of the Govt__ Department promoted courses | Y1: Name of the non-govt promoted courses__ done on own will | Z1: Name of the online platforms used by the teacher | AA1: Reason for perceived effectiveness of online or digital medium learning | AB1: Key response note on teacher's perception on digital learning | AC1: Any other general insights or information shared by teachers with respect to their digital learning engagement and preference | AD1: Key response note on DIKSHA course engagement and features | AE1: Specific feedback to improve the course quality | AF1: Key response or observation note Overall | AG1: Reason for not doing DIKSHA course | AH1: Key response on reasons for not doing DIKSHA courses | AI1: CLSS topics recalled | AJ1: Key response or feedback or observation on CLSS topics choice | AK1: Two things liked about CLSS | AL1: What makes a successful and helpful peer learning community | AM1: Instance of CLSS learning solving classroom challenge | AN1: Two things to be changed or done differently in CLSS | AO1: Usefulness and relevance of facilitation guide and PPT | AP1: Processes to cascade CLSS learnings at school level | AQ1: Key response note on current practice to cascade CLSS learning | AR1: Teachers suggestion on process and arrangement to promote cascade learning or peer learning at school level | AS1: What challenges do they face in filling attendance and feedback form post the samwad | AT1: Key response or observation note on teachers experience with CLSS attendance and other logistics | AU1: Reasons of non-participation in CLSS | AV1: Key response on CLSS non participation reasons | AW1: As per the teacher, how can CLSS be made more helpful for teachers | AX1: Key observation on teacher's motivation, awareness, challenges of non-participation | AY1: General perception on Teacher mentoring and classroom observation process | AZ1: What should be kept in mind by mentor official mentors while doing CRO & Mentoring | BA1: Support expectation from mentor and process | BB1: Any other suggestions to improve professional development support for teachers | BC1: Insight on teacher's motivation Intrinsic VS extrinsic with respect to professional development | BD1: Any unexpected insight, not in questionnaire | BE1: Are there any gender specific insights, concerns or suggestion highlighted or observed
A2: 1 | B2: Rashmi Mishra | C2: Vaibhav Tambe | D2: Bhind | E2: Male | F2: 46183 | G2: Social Science | H2: 24 | I2: Teacher daily takes 3 period which is fix. since he is the only teacher in the school, he has to take rest of subjects as well like Hindi and Sanskrit. | J2: Student documentations, Attendence, school level data collection (MDM/SIR/Election duty )and update into various platforms and portal. | K2: Being a individual teacher at school. he has to perform various academics and non-academics duties in a day. which is sometime very challenging for him as teacher and as HM | M2: Subject Training, CLSS, Digital Training (PLC) | N2: Throughout annual engagement teacher was involved in various activities (SIR, BLO Duty, Election Duty, Census, other data related work at school level ) | O2: real classroom demo video help to connect more during training. | P2: Margdarshika - Teaching Plan/Modules | R2: Teacher mentioned he has attended training and received margdarsika and used it but not very often. but not able to share the learning experience | T2: Teacher was not able to share any experience related to follow-up activities | V2: Network challenge | W2: Low engagement of students (they not able to connect the topic) , Low attendance, Lack of resources | X2: Education Department (DIET) | Z2: DIKSHA | AA2: Because online learning is not so useful. offline training is more effective and useful. | AB2: According to teacher online platform is not so effective for learning because it has not one to one interaction as training has. | AD2: Teacher were not able to recall what feature he find engaging. after giving prompt question, he was able to share one feature. | AH2: According to teacher he mentioned doing online course is not effective. | AK2: Get platform to share an experience and get a chance to co- create solutions | AL2: No response | AM2: No response | AN2: As Facilitator must have good communication to convey thoughts and learning. Resources and Infrastructure | AO2: He mentioned if teacher gets Facilitation guide and PPT then it will be useful. | AP2: Other | AQ2: Being a single teacher there is no benefit to share the same. | AS2: Not perceived important | AT2: Venue should be accessible and also with at least basic facilities | AU2: Others | AY2: according to teacher classroom observation means any official comes to classroom for observation on student assessment, syllabus completion. | AZ2: After giving prompt question teacher explained mentoring means - CAC/ Officials should support in classroom process, take lectures when it required | BA2: Officials should identify actual support and requirements of teachers and plan accordingly | BF2: Good
